[2022-08-11 10:34:23 ()] | [30]: discord.client > PyNaCl is not installed, voice will NOT be supported
[2022-08-11 10:34:23 ()] | [20]: discord.client > logging in using static token
[2022-08-11 10:34:24 ()] | [20]: ext.dev.evaluator > ext.dev.evaluator initialized
[2022-08-11 10:34:24 ()] | [20]: discord.gateway > Shard ID None has sent the IDENTIFY payload.
[2022-08-11 10:34:24 ()] | [20]: discord.gateway > Shard ID None has connected to Gateway (Session ID: 84b1fbd87d4bbe2b8b7108fb6f60d3c0).
[2022-08-11 10:35:06 ()] | [40]: asyncio > Task exception was never retrieved
future: <Task finished name='discord-ui-view-dispatch-b03f271965c30319554808c66b5c3558' coro=<View._scheduled_task() done, defined at /home/arc/club/pyhnix-beta/.venv/lib/python3.8/site-packages/discord/ui/view.py:414> exception=TypeError('_title() takes 2 positional arguments but 3 were given')>
Traceback (most recent call last):
  File "/home/arc/club/pyhnix-beta/.venv/lib/python3.8/site-packages/discord/ui/view.py", line 425, in _scheduled_task
    return await self.on_error(interaction, e, item)
  File "/home/arc/club/pyhnix-beta/ext/embed_builder.py", line 179, in on_error
    raise error
  File "/home/arc/club/pyhnix-beta/.venv/lib/python3.8/site-packages/discord/ui/view.py", line 423, in _scheduled_task
    await item.callback(interaction)
  File "/home/arc/club/pyhnix-beta/.venv/lib/python3.8/site-packages/discord/ui/view.py", line 138, in __call__
    return self.callback(self.view, interaction, self.item)
TypeError: _title() takes 2 positional arguments but 3 were given
[2022-08-11 10:35:29 ()] | [40]: asyncio > Task exception was never retrieved
future: <Task finished name='discord-ui-view-dispatch-b03f271965c30319554808c66b5c3558' coro=<View._scheduled_task() done, defined at /home/arc/club/pyhnix-beta/.venv/lib/python3.8/site-packages/discord/ui/view.py:414> exception=TypeError('_description() takes 2 positional arguments but 3 were given')>
Traceback (most recent call last):
  File "/home/arc/club/pyhnix-beta/.venv/lib/python3.8/site-packages/discord/ui/view.py", line 425, in _scheduled_task
    return await self.on_error(interaction, e, item)
  File "/home/arc/club/pyhnix-beta/ext/embed_builder.py", line 179, in on_error
    raise error
  File "/home/arc/club/pyhnix-beta/.venv/lib/python3.8/site-packages/discord/ui/view.py", line 423, in _scheduled_task
    await item.callback(interaction)
  File "/home/arc/club/pyhnix-beta/.venv/lib/python3.8/site-packages/discord/ui/view.py", line 138, in __call__
    return self.callback(self.view, interaction, self.item)
TypeError: _description() takes 2 positional arguments but 3 were given
[2022-08-11 10:35:33 ()] | [40]: asyncio > Task exception was never retrieved
future: <Task finished name='discord-ui-view-dispatch-b03f271965c30319554808c66b5c3558' coro=<View._scheduled_task() done, defined at /home/arc/club/pyhnix-beta/.venv/lib/python3.8/site-packages/discord/ui/view.py:414> exception=TypeError('_color() takes 2 positional arguments but 3 were given')>
Traceback (most recent call last):
  File "/home/arc/club/pyhnix-beta/.venv/lib/python3.8/site-packages/discord/ui/view.py", line 425, in _scheduled_task
    return await self.on_error(interaction, e, item)
  File "/home/arc/club/pyhnix-beta/ext/embed_builder.py", line 179, in on_error
    raise error
  File "/home/arc/club/pyhnix-beta/.venv/lib/python3.8/site-packages/discord/ui/view.py", line 423, in _scheduled_task
    await item.callback(interaction)
  File "/home/arc/club/pyhnix-beta/.venv/lib/python3.8/site-packages/discord/ui/view.py", line 138, in __call__
    return self.callback(self.view, interaction, self.item)
TypeError: _color() takes 2 positional arguments but 3 were given
[2022-08-11 10:35:37 ()] | [40]: asyncio > Task exception was never retrieved
future: <Task finished name='discord-ui-view-dispatch-b03f271965c30319554808c66b5c3558' coro=<View._scheduled_task() done, defined at /home/arc/club/pyhnix-beta/.venv/lib/python3.8/site-packages/discord/ui/view.py:414> exception=TypeError('_url() takes 2 positional arguments but 3 were given')>
Traceback (most recent call last):
  File "/home/arc/club/pyhnix-beta/.venv/lib/python3.8/site-packages/discord/ui/view.py", line 425, in _scheduled_task
    return await self.on_error(interaction, e, item)
  File "/home/arc/club/pyhnix-beta/ext/embed_builder.py", line 179, in on_error
    raise error
  File "/home/arc/club/pyhnix-beta/.venv/lib/python3.8/site-packages/discord/ui/view.py", line 423, in _scheduled_task
    await item.callback(interaction)
  File "/home/arc/club/pyhnix-beta/.venv/lib/python3.8/site-packages/discord/ui/view.py", line 138, in __call__
    return self.callback(self.view, interaction, self.item)
TypeError: _url() takes 2 positional arguments but 3 were given
[2022-08-11 11:02:19 ()] | [30]: discord.client > PyNaCl is not installed, voice will NOT be supported
[2022-08-11 11:02:19 ()] | [20]: discord.client > logging in using static token
[2022-08-11 11:02:19 ()] | [20]: ext.dev.evaluator > ext.dev.evaluator initialized
[2022-08-11 11:02:19 ()] | [20]: discord.gateway > Shard ID None has sent the IDENTIFY payload.
[2022-08-11 11:02:19 ()] | [20]: discord.gateway > Shard ID None has connected to Gateway (Session ID: 14b0384ef3342755afa8dcf46ce973a1).
[2022-08-11 11:02:31 ()] | [40]: ext.embed_builder > an error occurred, _title() takes 2 positional arguments but 3 were given
[2022-08-11 11:02:31 ()] | [40]: asyncio > Task exception was never retrieved
future: <Task finished name='discord-ui-view-dispatch-af6c9d5a24ed7572084a91a09db7598b' coro=<View._scheduled_task() done, defined at /home/arc/club/pyhnix-beta/.venv/lib/python3.8/site-packages/discord/ui/view.py:414> exception=TypeError('_title() takes 2 positional arguments but 3 were given')>
Traceback (most recent call last):
  File "/home/arc/club/pyhnix-beta/.venv/lib/python3.8/site-packages/discord/ui/view.py", line 425, in _scheduled_task
    return await self.on_error(interaction, e, item)
  File "/home/arc/club/pyhnix-beta/ext/embed_builder.py", line 184, in on_error
    raise error
  File "/home/arc/club/pyhnix-beta/.venv/lib/python3.8/site-packages/discord/ui/view.py", line 423, in _scheduled_task
    await item.callback(interaction)
  File "/home/arc/club/pyhnix-beta/.venv/lib/python3.8/site-packages/discord/ui/view.py", line 138, in __call__
    return self.callback(self.view, interaction, self.item)
TypeError: _title() takes 2 positional arguments but 3 were given
[2022-08-11 11:04:03 ()] | [30]: discord.client > PyNaCl is not installed, voice will NOT be supported
[2022-08-11 11:04:03 ()] | [20]: discord.client > logging in using static token
[2022-08-11 11:04:03 ()] | [20]: ext.dev.evaluator > ext.dev.evaluator initialized
[2022-08-11 11:04:03 ()] | [20]: discord.gateway > Shard ID None has sent the IDENTIFY payload.
[2022-08-11 11:04:03 ()] | [20]: discord.gateway > Shard ID None has connected to Gateway (Session ID: 43b0435cf83e623db82274e8ba3295c3).
[2022-08-11 11:04:16 ()] | [40]: ext.embed_builder > an error occurred, _title() takes 2 positional arguments but 3 were given
[2022-08-11 11:04:16 ()] | [40]: asyncio > Task exception was never retrieved
future: <Task finished name='discord-ui-view-dispatch-b7a50af76487aaf57c6a6f15c916e828' coro=<View._scheduled_task() done, defined at /home/arc/club/pyhnix-beta/.venv/lib/python3.8/site-packages/discord/ui/view.py:414> exception=TypeError('_title() takes 2 positional arguments but 3 were given')>
Traceback (most recent call last):
  File "/home/arc/club/pyhnix-beta/.venv/lib/python3.8/site-packages/discord/ui/view.py", line 425, in _scheduled_task
    return await self.on_error(interaction, e, item)
  File "/home/arc/club/pyhnix-beta/ext/embed_builder.py", line 188, in on_error
    raise error
  File "/home/arc/club/pyhnix-beta/.venv/lib/python3.8/site-packages/discord/ui/view.py", line 423, in _scheduled_task
    await item.callback(interaction)
  File "/home/arc/club/pyhnix-beta/.venv/lib/python3.8/site-packages/discord/ui/view.py", line 138, in __call__
    return self.callback(self.view, interaction, self.item)
TypeError: _title() takes 2 positional arguments but 3 were given
[2022-08-11 11:05:05 ()] | [40]: ext.embed_builder > an error occurred, _title() takes 2 positional arguments but 3 were given
[2022-08-11 11:05:05 ()] | [40]: asyncio > Task exception was never retrieved
future: <Task finished name='discord-ui-view-dispatch-a80194e3932640b2f2a856dce391decc' coro=<View._scheduled_task() done, defined at /home/arc/club/pyhnix-beta/.venv/lib/python3.8/site-packages/discord/ui/view.py:414> exception=TypeError('_title() takes 2 positional arguments but 3 were given')>
Traceback (most recent call last):
  File "/home/arc/club/pyhnix-beta/.venv/lib/python3.8/site-packages/discord/ui/view.py", line 425, in _scheduled_task
    return await self.on_error(interaction, e, item)
  File "/home/arc/club/pyhnix-beta/ext/embed_builder.py", line 188, in on_error
    raise error
  File "/home/arc/club/pyhnix-beta/.venv/lib/python3.8/site-packages/discord/ui/view.py", line 423, in _scheduled_task
    await item.callback(interaction)
  File "/home/arc/club/pyhnix-beta/.venv/lib/python3.8/site-packages/discord/ui/view.py", line 138, in __call__
    return self.callback(self.view, interaction, self.item)
TypeError: _title() takes 2 positional arguments but 3 were given
[2022-08-11 11:07:02 ()] | [40]: ext.embed_builder > an error occurred, _title() takes 2 positional arguments but 3 were given
[2022-08-11 11:07:02 ()] | [40]: asyncio > Task exception was never retrieved
future: <Task finished name='discord-ui-view-dispatch-1b8f1522fc6a0bd8f77cbc064f243982' coro=<View._scheduled_task() done, defined at /home/arc/club/pyhnix-beta/.venv/lib/python3.8/site-packages/discord/ui/view.py:414> exception=TypeError('_title() takes 2 positional arguments but 3 were given')>
Traceback (most recent call last):
  File "/home/arc/club/pyhnix-beta/.venv/lib/python3.8/site-packages/discord/ui/view.py", line 425, in _scheduled_task
    return await self.on_error(interaction, e, item)
  File "/home/arc/club/pyhnix-beta/ext/embed_builder.py", line 188, in on_error
    raise error
  File "/home/arc/club/pyhnix-beta/.venv/lib/python3.8/site-packages/discord/ui/view.py", line 423, in _scheduled_task
    await item.callback(interaction)
  File "/home/arc/club/pyhnix-beta/.venv/lib/python3.8/site-packages/discord/ui/view.py", line 138, in __call__
    return self.callback(self.view, interaction, self.item)
TypeError: _title() takes 2 positional arguments but 3 were given
[2022-08-11 12:19:05 ()] | [30]: discord.client > PyNaCl is not installed, voice will NOT be supported
[2022-08-11 12:19:05 ()] | [20]: discord.client > logging in using static token
[2022-08-11 12:19:06 ()] | [20]: ext.dev.evaluator > ext.dev.evaluator initialized
[2022-08-11 12:19:06 ()] | [20]: discord.gateway > Shard ID None has sent the IDENTIFY payload.
[2022-08-11 12:19:06 ()] | [20]: discord.gateway > Shard ID None has connected to Gateway (Session ID: 492a994182e9a1ff0ce40e7a291ce78b).
[2022-08-11 12:19:13 ()] | [40]: ext.embed_builder > an error occurred, _title() takes 2 positional arguments but 3 were given
[2022-08-11 12:19:13 ()] | [40]: asyncio > Task exception was never retrieved
future: <Task finished name='discord-ui-view-dispatch-27eb76e0d23b69e244b3d61ca01f55ff' coro=<View._scheduled_task() done, defined at /home/arc/club/pyhnix-beta/.venv/lib/python3.8/site-packages/discord/ui/view.py:414> exception=TypeError('_title() takes 2 positional arguments but 3 were given')>
Traceback (most recent call last):
  File "/home/arc/club/pyhnix-beta/.venv/lib/python3.8/site-packages/discord/ui/view.py", line 425, in _scheduled_task
    return await self.on_error(interaction, e, item)
  File "/home/arc/club/pyhnix-beta/ext/embed_builder.py", line 188, in on_error
    raise error
  File "/home/arc/club/pyhnix-beta/.venv/lib/python3.8/site-packages/discord/ui/view.py", line 423, in _scheduled_task
    await item.callback(interaction)
  File "/home/arc/club/pyhnix-beta/.venv/lib/python3.8/site-packages/discord/ui/view.py", line 138, in __call__
    return self.callback(self.view, interaction, self.item)
TypeError: _title() takes 2 positional arguments but 3 were given
[2022-08-11 12:20:21 ()] | [40]: ext.embed_builder > an error occurred, __init__() got multiple values for argument 'callback'
[2022-08-11 12:20:21 ()] | [40]: asyncio > Task exception was never retrieved
future: <Task finished name='discord-ui-view-dispatch-24ddd59ccdb87926a0df9d172b6f56eb' coro=<View._scheduled_task() done, defined at /home/arc/club/pyhnix-beta/.venv/lib/python3.8/site-packages/discord/ui/view.py:414> exception=TypeError("__init__() got multiple values for argument 'callback'")>
Traceback (most recent call last):
  File "/home/arc/club/pyhnix-beta/.venv/lib/python3.8/site-packages/discord/ui/view.py", line 425, in _scheduled_task
    return await self.on_error(interaction, e, item)
  File "/home/arc/club/pyhnix-beta/ext/embed_builder.py", line 188, in on_error
    raise error
  File "/home/arc/club/pyhnix-beta/.venv/lib/python3.8/site-packages/discord/ui/view.py", line 423, in _scheduled_task
    await item.callback(interaction)
  File "/home/arc/club/pyhnix-beta/ext/embed_builder.py", line 57, in _title
    title_form = Form("Title", callback=callback, title=title_in)
TypeError: __init__() got multiple values for argument 'callback'
[2022-08-11 12:20:51 ()] | [40]: ext.embed_builder > an error occurred, __init__() got multiple values for argument 'callback'
[2022-08-11 12:20:51 ()] | [40]: asyncio > Task exception was never retrieved
future: <Task finished name='discord-ui-view-dispatch-8f53dc30fe6e5056b892e50d78504a91' coro=<View._scheduled_task() done, defined at /home/arc/club/pyhnix-beta/.venv/lib/python3.8/site-packages/discord/ui/view.py:414> exception=TypeError("__init__() got multiple values for argument 'callback'")>
Traceback (most recent call last):
  File "/home/arc/club/pyhnix-beta/.venv/lib/python3.8/site-packages/discord/ui/view.py", line 425, in _scheduled_task
    return await self.on_error(interaction, e, item)
  File "/home/arc/club/pyhnix-beta/ext/embed_builder.py", line 188, in on_error
    raise error
  File "/home/arc/club/pyhnix-beta/.venv/lib/python3.8/site-packages/discord/ui/view.py", line 423, in _scheduled_task
    await item.callback(interaction)
  File "/home/arc/club/pyhnix-beta/ext/embed_builder.py", line 57, in _title
    title_form = Form("Title", callback=callback, title=title_in)
TypeError: __init__() got multiple values for argument 'callback'
[2022-08-11 12:32:00 ()] | [30]: discord.client > PyNaCl is not installed, voice will NOT be supported
[2022-08-11 12:32:00 ()] | [20]: discord.client > logging in using static token
[2022-08-11 12:32:00 ()] | [20]: ext.dev.evaluator > ext.dev.evaluator initialized
[2022-08-11 12:32:00 ()] | [20]: discord.gateway > Shard ID None has sent the IDENTIFY payload.
[2022-08-11 12:32:01 ()] | [20]: discord.gateway > Shard ID None has connected to Gateway (Session ID: 892c7babf65e59aa77371132aaf89b42).
[2022-08-11 12:32:39 ()] | [20]: discord.client > logging in using static token
[2022-08-11 12:32:39 ()] | [20]: ext.dev.evaluator > ext.dev.evaluator initialized
[2022-08-11 12:32:39 ()] | [20]: discord.gateway > Shard ID None has sent the IDENTIFY payload.
[2022-08-11 12:32:40 ()] | [20]: discord.gateway > Shard ID None has connected to Gateway (Session ID: 777c78c5cba44cd5b270b8fbf47dcce5).
[2022-08-11 12:36:10 ()] | [30]: discord.client > PyNaCl is not installed, voice will NOT be supported
[2022-08-11 12:36:10 ()] | [20]: discord.client > logging in using static token
[2022-08-11 12:36:10 ()] | [20]: ext.dev.evaluator > ext.dev.evaluator initialized
[2022-08-11 12:36:11 ()] | [20]: discord.gateway > Shard ID None has sent the IDENTIFY payload.
[2022-08-11 12:36:11 ()] | [20]: discord.gateway > Shard ID None has connected to Gateway (Session ID: 2b44e5177b05b6f2176c1fbc602451b8).
[2022-08-11 12:36:25 ()] | [20]: discord.client > logging in using static token
[2022-08-11 12:36:25 ()] | [20]: ext.dev.evaluator > ext.dev.evaluator initialized
[2022-08-11 12:36:25 ()] | [20]: discord.gateway > Shard ID None has sent the IDENTIFY payload.
[2022-08-11 12:36:26 ()] | [20]: discord.gateway > Shard ID None has connected to Gateway (Session ID: afbf6f3efc9fa336898e382a75da5a43).
[2022-08-11 12:41:37 ()] | [20]: ext.dev.evaluator > ext.dev.evaluator initialized
[2022-08-11 12:42:51 ()] | [20]: ext.dev.evaluator > ext.dev.evaluator initialized
[2022-08-11 12:44:03 ()] | [40]: ext.embed_builder > an error occurred, __init__() got multiple values for argument 'callback'
[2022-08-11 12:44:03 ()] | [40]: asyncio > Task exception was never retrieved
future: <Task finished name='discord-ui-view-dispatch-8cf1a64ffb4063f763ad2678a7e64b53' coro=<View._scheduled_task() done, defined at /home/arc/club/pyhnix-beta/.venv/lib/python3.8/site-packages/discord/ui/view.py:414> exception=TypeError("__init__() got multiple values for argument 'callback'")>
Traceback (most recent call last):
  File "/home/arc/club/pyhnix-beta/.venv/lib/python3.8/site-packages/discord/ui/view.py", line 425, in _scheduled_task
    return await self.on_error(interaction, e, item)
  File "/home/arc/club/pyhnix-beta/ext/embed_builder.py", line 188, in on_error
    raise error
  File "/home/arc/club/pyhnix-beta/.venv/lib/python3.8/site-packages/discord/ui/view.py", line 423, in _scheduled_task
    await item.callback(interaction)
  File "/home/arc/club/pyhnix-beta/ext/embed_builder.py", line 57, in _title
    title_form = Form("Title", callback=callback, title=title_in)
TypeError: __init__() got multiple values for argument 'callback'
[2022-08-11 13:52:05 ()] | [40]: ext.embed_builder > an error occurred, Modal must have a title
[2022-08-11 13:52:05 ()] | [40]: asyncio > Task exception was never retrieved
future: <Task finished name='discord-ui-view-dispatch-7f040c18b22b8d233dcb5c922099ef59' coro=<View._scheduled_task() done, defined at /home/arc/club/pyhnix-beta/.venv/lib/python3.8/site-packages/discord/ui/view.py:414> exception=ValueError('Modal must have a title')>
Traceback (most recent call last):
  File "/home/arc/club/pyhnix-beta/.venv/lib/python3.8/site-packages/discord/ui/view.py", line 425, in _scheduled_task
    return await self.on_error(interaction, e, item)
  File "/home/arc/club/pyhnix-beta/ext/embed_builder.py", line 188, in on_error
    raise error
  File "/home/arc/club/pyhnix-beta/.venv/lib/python3.8/site-packages/discord/ui/view.py", line 423, in _scheduled_task
    await item.callback(interaction)
  File "/home/arc/club/pyhnix-beta/ext/embed_builder.py", line 57, in _title
    title_form = Form("Title", callback=callback, title=title_in)
  File "/home/arc/club/pyhnix-beta/ext/embed_builder.py", line 16, in __init__
    super().__init__()
  File "/home/arc/club/pyhnix-beta/.venv/lib/python3.8/site-packages/discord/ui/modal.py", line 130, in __init__
    raise ValueError('Modal must have a title')
ValueError: Modal must have a title
[2022-08-11 13:52:46 ()] | [40]: ext.embed_builder > an error occurred, expected Item not <class 'function'>
[2022-08-11 13:52:46 ()] | [40]: asyncio > Task exception was never retrieved
future: <Task finished name='discord-ui-view-dispatch-62659f7efedd87db202775c53a6c558d' coro=<View._scheduled_task() done, defined at /home/arc/club/pyhnix-beta/.venv/lib/python3.8/site-packages/discord/ui/view.py:414> exception=TypeError("expected Item not <class 'function'>")>
Traceback (most recent call last):
  File "/home/arc/club/pyhnix-beta/.venv/lib/python3.8/site-packages/discord/ui/view.py", line 425, in _scheduled_task
    return await self.on_error(interaction, e, item)
  File "/home/arc/club/pyhnix-beta/ext/embed_builder.py", line 188, in on_error
    raise error
  File "/home/arc/club/pyhnix-beta/.venv/lib/python3.8/site-packages/discord/ui/view.py", line 423, in _scheduled_task
    await item.callback(interaction)
  File "/home/arc/club/pyhnix-beta/ext/embed_builder.py", line 57, in _title
    title_form = Form("Title", callback=callback, title=title_in)
  File "/home/arc/club/pyhnix-beta/ext/embed_builder.py", line 22, in __init__
    self.add_item(item)
  File "/home/arc/club/pyhnix-beta/.venv/lib/python3.8/site-packages/discord/ui/view.py", line 322, in add_item
    raise TypeError(f'expected Item not {item.__class__!r}')
TypeError: expected Item not <class 'function'>
[2022-08-11 13:53:41 ()] | [40]: asyncio > Task exception was never retrieved
future: <Task finished name='discord-ui-modal-dispatch-4977a38c2ab1265ed5ad8e7591ec49ca' coro=<Modal._scheduled_task() done, defined at /home/arc/club/pyhnix-beta/.venv/lib/python3.8/site-packages/discord/ui/modal.py:177> exception=TypeError('Object of type TextInput is not JSON serializable')>
Traceback (most recent call last):
  File "/home/arc/club/pyhnix-beta/.venv/lib/python3.8/site-packages/discord/ui/modal.py", line 186, in _scheduled_task
    return await self.on_error(interaction, e)
  File "/home/arc/club/pyhnix-beta/ext/embed_builder.py", line 32, in on_error
    raise error
  File "/home/arc/club/pyhnix-beta/.venv/lib/python3.8/site-packages/discord/ui/modal.py", line 184, in _scheduled_task
    await self.on_submit(interaction)
  File "/home/arc/club/pyhnix-beta/ext/embed_builder.py", line 28, in on_submit
    await self.callback(self, interaction)
  File "/home/arc/club/pyhnix-beta/ext/embed_builder.py", line 54, in callback
    await new_interaction.response.edit_message(embed=self.embed)
  File "/home/arc/club/pyhnix-beta/.venv/lib/python3.8/site-packages/discord/interactions.py", line 807, in edit_message
    await adapter.create_interaction_response(
  File "/home/arc/club/pyhnix-beta/.venv/lib/python3.8/site-packages/discord/webhook/async_.py", line 150, in request
    to_send = utils._to_json(payload)
  File "/home/arc/club/pyhnix-beta/.venv/lib/python3.8/site-packages/discord/utils.py", line 620, in _to_json
    return json.dumps(obj, separators=(',', ':'), ensure_ascii=True)
  File "/home/arc/.pyenv/versions/3.8.11/lib/python3.8/json/__init__.py", line 234, in dumps
    return cls(
  File "/home/arc/.pyenv/versions/3.8.11/lib/python3.8/json/encoder.py", line 199, in encode
    chunks = self.iterencode(o, _one_shot=True)
  File "/home/arc/.pyenv/versions/3.8.11/lib/python3.8/json/encoder.py", line 257, in iterencode
    return _iterencode(o, 0)
  File "/home/arc/.pyenv/versions/3.8.11/lib/python3.8/json/encoder.py", line 179, in default
    raise TypeError(f'Object of type {o.__class__.__name__} '
TypeError: Object of type TextInput is not JSON serializable
[2022-08-12 10:41:04 ()] | [20]: ext.dev.evaluator > ext.dev.evaluator initialized
[2022-08-12 10:41:19 ()] | [40]: asyncio > Task exception was never retrieved
future: <Task finished name='discord-ui-modal-dispatch-ba0b3e86929786a7cdc5f1d9f48898ca' coro=<Modal._scheduled_task() done, defined at /home/arc/club/pyhnix-beta/.venv/lib/python3.8/site-packages/discord/ui/modal.py:177> exception=HTTPException('400 Bad Request (error code: 50035): Invalid Form Body\nIn embeds.0.description: This field is required')>
Traceback (most recent call last):
  File "/home/arc/club/pyhnix-beta/.venv/lib/python3.8/site-packages/discord/ui/modal.py", line 186, in _scheduled_task
    return await self.on_error(interaction, e)
  File "/home/arc/club/pyhnix-beta/ext/embed_builder.py", line 32, in on_error
    raise error
  File "/home/arc/club/pyhnix-beta/.venv/lib/python3.8/site-packages/discord/ui/modal.py", line 184, in _scheduled_task
    await self.on_submit(interaction)
  File "/home/arc/club/pyhnix-beta/ext/embed_builder.py", line 28, in on_submit
    await self.callback(self, interaction)
  File "/home/arc/club/pyhnix-beta/ext/embed_builder.py", line 54, in callback
    await new_interaction.response.edit_message(embed=self.embed)
  File "/home/arc/club/pyhnix-beta/.venv/lib/python3.8/site-packages/discord/interactions.py", line 807, in edit_message
    await adapter.create_interaction_response(
  File "/home/arc/club/pyhnix-beta/.venv/lib/python3.8/site-packages/discord/webhook/async_.py", line 221, in request
    raise HTTPException(response, data)
discord.errors.HTTPException: 400 Bad Request (error code: 50035): Invalid Form Body
In embeds.0.description: This field is required
[2022-08-12 10:46:18 ()] | [40]: ext.embed_builder > an error occurred, edit_message() missing 1 required positional argument: 'message_id'
[2022-08-12 10:46:18 ()] | [40]: asyncio > Task exception was never retrieved
future: <Task finished name='discord-ui-view-dispatch-cc72311cfea05206057b0dc0b9b16087' coro=<View._scheduled_task() done, defined at /home/arc/club/pyhnix-beta/.venv/lib/python3.8/site-packages/discord/ui/view.py:414> exception=TypeError("edit_message() missing 1 required positional argument: 'message_id'")>
Traceback (most recent call last):
  File "/home/arc/club/pyhnix-beta/.venv/lib/python3.8/site-packages/discord/ui/view.py", line 425, in _scheduled_task
    return await self.on_error(interaction, e, item)
  File "/home/arc/club/pyhnix-beta/ext/embed_builder.py", line 177, in on_error
    raise error
  File "/home/arc/club/pyhnix-beta/.venv/lib/python3.8/site-packages/discord/ui/view.py", line 423, in _scheduled_task
    await item.callback(interaction)
  File "/home/arc/club/pyhnix-beta/ext/embed_builder.py", line 53, in _title
    await interaction.followup.edit_message(embed=self.embed)
TypeError: edit_message() missing 1 required positional argument: 'message_id'
[2022-08-12 10:47:19 ()] | [40]: ext.embed_builder > an error occurred, This interaction has already been responded to before
[2022-08-12 10:47:19 ()] | [40]: asyncio > Task exception was never retrieved
future: <Task finished name='discord-ui-view-dispatch-adc848f5abbb1de6df67f9d82f0ba90b' coro=<View._scheduled_task() done, defined at /home/arc/club/pyhnix-beta/.venv/lib/python3.8/site-packages/discord/ui/view.py:414> exception=InteractionResponded('This interaction has already been responded to before')>
Traceback (most recent call last):
  File "/home/arc/club/pyhnix-beta/.venv/lib/python3.8/site-packages/discord/ui/view.py", line 425, in _scheduled_task
    return await self.on_error(interaction, e, item)
  File "/home/arc/club/pyhnix-beta/ext/embed_builder.py", line 177, in on_error
    raise error
  File "/home/arc/club/pyhnix-beta/.venv/lib/python3.8/site-packages/discord/ui/view.py", line 423, in _scheduled_task
    await item.callback(interaction)
  File "/home/arc/club/pyhnix-beta/ext/embed_builder.py", line 53, in _title
    await interaction.response.edit_message(embed=self.embed)
  File "/home/arc/club/pyhnix-beta/.venv/lib/python3.8/site-packages/discord/interactions.py", line 782, in edit_message
    raise InteractionResponded(self._parent)
discord.errors.InteractionResponded: This interaction has already been responded to before
[2022-08-12 10:51:33 ()] | [40]: ext.embed_builder > an error occurred, edit_message() got an unexpected keyword argument 'message_id'
[2022-08-12 10:51:33 ()] | [40]: asyncio > Task exception was never retrieved
future: <Task finished name='discord-ui-view-dispatch-43c1da9df47186cb472587dbc012eebb' coro=<View._scheduled_task() done, defined at /home/arc/club/pyhnix-beta/.venv/lib/python3.8/site-packages/discord/ui/view.py:414> exception=TypeError("edit_message() got an unexpected keyword argument 'message_id'")>
Traceback (most recent call last):
  File "/home/arc/club/pyhnix-beta/.venv/lib/python3.8/site-packages/discord/ui/view.py", line 425, in _scheduled_task
    return await self.on_error(interaction, e, item)
  File "/home/arc/club/pyhnix-beta/ext/embed_builder.py", line 177, in on_error
    raise error
  File "/home/arc/club/pyhnix-beta/.venv/lib/python3.8/site-packages/discord/ui/view.py", line 423, in _scheduled_task
    await item.callback(interaction)
  File "/home/arc/club/pyhnix-beta/ext/embed_builder.py", line 53, in _title
    await interaction.response.edit_message(embed=self.embed, message_id=interaction.message.id)
TypeError: edit_message() got an unexpected keyword argument 'message_id'
[2022-08-12 10:55:45 ()] | [40]: ext.embed_builder > an error occurred, 400 Bad Request (error code: 50035): Invalid Form Body
In embeds.0.description: This field is required
[2022-08-12 10:55:45 ()] | [40]: asyncio > Task exception was never retrieved
future: <Task finished name='discord-ui-view-dispatch-1bc2896e7bd657c2d1b3f95c4ed9bf31' coro=<View._scheduled_task() done, defined at /home/arc/club/pyhnix-beta/.venv/lib/python3.8/site-packages/discord/ui/view.py:414> exception=TypeError('Expected discord.Colour, int, or None but received method instead.')>
Traceback (most recent call last):
  File "/home/arc/club/pyhnix-beta/.venv/lib/python3.8/site-packages/discord/ui/view.py", line 423, in _scheduled_task
    await item.callback(interaction)
  File "/home/arc/club/pyhnix-beta/ext/embed_builder.py", line 56, in _title
    await interaction.followup.edit_message(embed=self.embed, message_id=interaction.message.id)
  File "/home/arc/club/pyhnix-beta/.venv/lib/python3.8/site-packages/discord/webhook/async_.py", line 1901, in edit_message
    data = await adapter.edit_webhook_message(
  File "/home/arc/club/pyhnix-beta/.venv/lib/python3.8/site-packages/discord/webhook/async_.py", line 221, in request
    raise HTTPException(response, data)
discord.errors.HTTPException: 400 Bad Request (error code: 50035): Invalid Form Body
In embeds.0.description: This field is required

During handling of the above exception, another exception occurred:

Traceback (most recent call last):
  File "/home/arc/club/pyhnix-beta/.venv/lib/python3.8/site-packages/discord/ui/view.py", line 425, in _scheduled_task
    return await self.on_error(interaction, e, item)
  File "/home/arc/club/pyhnix-beta/ext/embed_builder.py", line 169, in on_error
    embed = discord.Embed(
  File "/home/arc/club/pyhnix-beta/.venv/lib/python3.8/site-packages/discord/embeds.py", line 179, in __init__
    self.colour = colour if colour is not None else color
  File "/home/arc/club/pyhnix-beta/.venv/lib/python3.8/site-packages/discord/embeds.py", line 323, in colour
    raise TypeError(f'Expected discord.Colour, int, or None but received {value.__class__.__name__} instead.')
TypeError: Expected discord.Colour, int, or None but received method instead.
[2022-08-12 10:57:12 ()] | [40]: ext.embed_builder > an error occurred, 400 Bad Request (error code: 50035): Invalid Form Body
In embeds.0.description: This field is required
[2022-08-12 10:57:49 ()] | [40]: ext.embed_builder > an error occurred, 400 Bad Request (error code: 50035): Invalid Form Body
In embeds.0.description: This field is required
[2022-08-12 10:58:16 ()] | [40]: ext.embed_builder > an error occurred, expected Item not <class 'function'>
[2022-08-12 10:58:16 ()] | [40]: asyncio > Task exception was never retrieved
future: <Task finished name='discord-ui-view-dispatch-7e387194cebedc58b04d31555c20996a' coro=<View._scheduled_task() done, defined at /home/arc/club/pyhnix-beta/.venv/lib/python3.8/site-packages/discord/ui/view.py:414> exception=TypeError("expected Item not <class 'function'>")>
Traceback (most recent call last):
  File "/home/arc/club/pyhnix-beta/.venv/lib/python3.8/site-packages/discord/ui/view.py", line 425, in _scheduled_task
    return await self.on_error(interaction, e, item)
  File "/home/arc/club/pyhnix-beta/ext/embed_builder.py", line 180, in on_error
    raise error
  File "/home/arc/club/pyhnix-beta/.venv/lib/python3.8/site-packages/discord/ui/view.py", line 423, in _scheduled_task
    await item.callback(interaction)
  File "/home/arc/club/pyhnix-beta/ext/embed_builder.py", line 91, in _color
    color_form = Form(callback=callback, color=color_in)
  File "/home/arc/club/pyhnix-beta/ext/embed_builder.py", line 21, in __init__
    self.add_item(item)
  File "/home/arc/club/pyhnix-beta/.venv/lib/python3.8/site-packages/discord/ui/view.py", line 322, in add_item
    raise TypeError(f'expected Item not {item.__class__!r}')
TypeError: expected Item not <class 'function'>
[2022-08-12 11:01:13 ()] | [40]: ext.embed_builder > an error occurred, expected Item not <class 'function'>
[2022-08-12 11:01:13 ()] | [40]: asyncio > Task exception was never retrieved
future: <Task finished name='discord-ui-view-dispatch-7e387194cebedc58b04d31555c20996a' coro=<View._scheduled_task() done, defined at /home/arc/club/pyhnix-beta/.venv/lib/python3.8/site-packages/discord/ui/view.py:414> exception=TypeError("expected Item not <class 'function'>")>
Traceback (most recent call last):
  File "/home/arc/club/pyhnix-beta/.venv/lib/python3.8/site-packages/discord/ui/view.py", line 425, in _scheduled_task
    return await self.on_error(interaction, e, item)
  File "/home/arc/club/pyhnix-beta/ext/embed_builder.py", line 180, in on_error
    raise error
  File "/home/arc/club/pyhnix-beta/.venv/lib/python3.8/site-packages/discord/ui/view.py", line 423, in _scheduled_task
    await item.callback(interaction)
  File "/home/arc/club/pyhnix-beta/ext/embed_builder.py", line 111, in _url
    url_form = Form(callback=callback, url=url_in)
  File "/home/arc/club/pyhnix-beta/ext/embed_builder.py", line 21, in __init__
    self.add_item(item)
  File "/home/arc/club/pyhnix-beta/.venv/lib/python3.8/site-packages/discord/ui/view.py", line 322, in add_item
    raise TypeError(f'expected Item not {item.__class__!r}')
TypeError: expected Item not <class 'function'>
[2022-08-12 11:25:17 ()] | [40]: ext.embed_builder > an error occurred, unknown colour format given
[2022-08-12 11:25:17 ()] | [40]: asyncio > Task exception was never retrieved
future: <Task finished name='discord-ui-view-dispatch-205ab977b5d5e4401f0983921ab47acc' coro=<View._scheduled_task() done, defined at /home/arc/club/pyhnix-beta/.venv/lib/python3.8/site-packages/discord/ui/view.py:414> exception=ValueError('unknown colour format given')>
Traceback (most recent call last):
  File "/home/arc/club/pyhnix-beta/.venv/lib/python3.8/site-packages/discord/ui/view.py", line 425, in _scheduled_task
    return await self.on_error(interaction, e, item)
  File "/home/arc/club/pyhnix-beta/ext/embed_builder.py", line 174, in on_error
    raise error
  File "/home/arc/club/pyhnix-beta/.venv/lib/python3.8/site-packages/discord/ui/view.py", line 423, in _scheduled_task
    await item.callback(interaction)
  File "/home/arc/club/pyhnix-beta/ext/embed_builder.py", line 89, in _color
    self.embed.color = discord.Color.from_str(form.items['color'].value)
  File "/home/arc/club/pyhnix-beta/.venv/lib/python3.8/site-packages/discord/colour.py", line 208, in from_str
    raise ValueError('unknown colour format given')
ValueError: unknown colour format given
[2022-08-12 11:25:44 ()] | [40]: ext.embed_builder > an error occurred, 400 Bad Request (error code: 50035): Invalid Form Body
In embeds.0.url: Scheme "google.com" is not supported. Scheme must be one of ('http', 'https').
[2022-08-12 11:26:07 ()] | [40]: ext.embed_builder > an error occurred, 400 Bad Request (error code: 50035): Invalid Form Body
In embeds.0.url: Scheme "google.com" is not supported. Scheme must be one of ('http', 'https').
[2022-08-12 11:26:14 ()] | [40]: ext.embed_builder > an error occurred, 400 Bad Request (error code: 50035): Invalid Form Body
In embeds.0.url: Scheme "google.com" is not supported. Scheme must be one of ('http', 'https').
[2022-08-12 11:44:33 ()] | [40]: ext.embed_builder > an error occurred, Object of type Colour is not JSON serializable
[2022-08-12 11:44:33 ()] | [40]: asyncio > Task exception was never retrieved
future: <Task finished name='discord-ui-view-dispatch-77b9004f95e84616a154a2cb372a2321' coro=<View._scheduled_task() done, defined at /home/arc/club/pyhnix-beta/.venv/lib/python3.8/site-packages/discord/ui/view.py:414> exception=TypeError('Object of type Colour is not JSON serializable')>
Traceback (most recent call last):
  File "/home/arc/club/pyhnix-beta/.venv/lib/python3.8/site-packages/discord/ui/view.py", line 425, in _scheduled_task
    return await self.on_error(interaction, e, item)
  File "/home/arc/club/pyhnix-beta/ext/embed_builder.py", line 201, in on_error
    raise error
  File "/home/arc/club/pyhnix-beta/.venv/lib/python3.8/site-packages/discord/ui/view.py", line 423, in _scheduled_task
    await item.callback(interaction)
  File "/home/arc/club/pyhnix-beta/ext/embed_builder.py", line 109, in _color
    response = await self.prompt(
  File "/home/arc/club/pyhnix-beta/ext/embed_builder.py", line 54, in prompt
    await interaction.response.send_modal(form)
  File "/home/arc/club/pyhnix-beta/.venv/lib/python3.8/site-packages/discord/interactions.py", line 847, in send_modal
    await adapter.create_interaction_response(
  File "/home/arc/club/pyhnix-beta/.venv/lib/python3.8/site-packages/discord/webhook/async_.py", line 150, in request
    to_send = utils._to_json(payload)
  File "/home/arc/club/pyhnix-beta/.venv/lib/python3.8/site-packages/discord/utils.py", line 620, in _to_json
    return json.dumps(obj, separators=(',', ':'), ensure_ascii=True)
  File "/home/arc/.pyenv/versions/3.8.11/lib/python3.8/json/__init__.py", line 234, in dumps
    return cls(
  File "/home/arc/.pyenv/versions/3.8.11/lib/python3.8/json/encoder.py", line 199, in encode
    chunks = self.iterencode(o, _one_shot=True)
  File "/home/arc/.pyenv/versions/3.8.11/lib/python3.8/json/encoder.py", line 257, in iterencode
    return _iterencode(o, 0)
  File "/home/arc/.pyenv/versions/3.8.11/lib/python3.8/json/encoder.py", line 179, in default
    raise TypeError(f'Object of type {o.__class__.__name__} '
TypeError: Object of type Colour is not JSON serializable
[2022-08-12 11:59:31 ()] | [40]: ext.embed_builder > an error occurred, 401 Unauthorized (error code: 50027): Invalid Webhook Token
[2022-08-12 11:59:31 ()] | [40]: asyncio > Task exception was never retrieved
future: <Task finished name='discord-ui-view-dispatch-77b9004f95e84616a154a2cb372a2321' coro=<View._scheduled_task() done, defined at /home/arc/club/pyhnix-beta/.venv/lib/python3.8/site-packages/discord/ui/view.py:414> exception=HTTPException('401 Unauthorized (error code: 50027): Invalid Webhook Token')>
Traceback (most recent call last):
  File "/home/arc/club/pyhnix-beta/.venv/lib/python3.8/site-packages/discord/ui/view.py", line 423, in _scheduled_task
    await item.callback(interaction)
  File "/home/arc/club/pyhnix-beta/ext/embed_builder.py", line 134, in _url
    await self.update(interaction)
  File "/home/arc/club/pyhnix-beta/ext/embed_builder.py", line 65, in update
    await interaction.followup.edit_message(
  File "/home/arc/club/pyhnix-beta/.venv/lib/python3.8/site-packages/discord/webhook/async_.py", line 1901, in edit_message
    data = await adapter.edit_webhook_message(
  File "/home/arc/club/pyhnix-beta/.venv/lib/python3.8/site-packages/discord/webhook/async_.py", line 221, in request
    raise HTTPException(response, data)
discord.errors.HTTPException: 401 Unauthorized (error code: 50027): Invalid Webhook Token

During handling of the above exception, another exception occurred:

Traceback (most recent call last):
  File "/home/arc/club/pyhnix-beta/.venv/lib/python3.8/site-packages/discord/ui/view.py", line 425, in _scheduled_task
    return await self.on_error(interaction, e, item)
  File "/home/arc/club/pyhnix-beta/ext/embed_builder.py", line 196, in on_error
    await interaction.followup.send(
  File "/home/arc/club/pyhnix-beta/.venv/lib/python3.8/site-packages/discord/webhook/async_.py", line 1726, in send
    data = await adapter.execute_webhook(
  File "/home/arc/club/pyhnix-beta/.venv/lib/python3.8/site-packages/discord/webhook/async_.py", line 221, in request
    raise HTTPException(response, data)
discord.errors.HTTPException: 401 Unauthorized (error code: 50027): Invalid Webhook Token
[2022-08-12 11:59:39 ()] | [40]: ext.embed_builder > an error occurred, 401 Unauthorized (error code: 50027): Invalid Webhook Token
[2022-08-12 11:59:39 ()] | [40]: asyncio > Task exception was never retrieved
future: <Task finished name='discord-ui-view-dispatch-77b9004f95e84616a154a2cb372a2321' coro=<View._scheduled_task() done, defined at /home/arc/club/pyhnix-beta/.venv/lib/python3.8/site-packages/discord/ui/view.py:414> exception=HTTPException('401 Unauthorized (error code: 50027): Invalid Webhook Token')>
Traceback (most recent call last):
  File "/home/arc/club/pyhnix-beta/.venv/lib/python3.8/site-packages/discord/ui/view.py", line 423, in _scheduled_task
    await item.callback(interaction)
  File "/home/arc/club/pyhnix-beta/ext/embed_builder.py", line 101, in _description
    await self.update(interaction)
  File "/home/arc/club/pyhnix-beta/ext/embed_builder.py", line 65, in update
    await interaction.followup.edit_message(
  File "/home/arc/club/pyhnix-beta/.venv/lib/python3.8/site-packages/discord/webhook/async_.py", line 1901, in edit_message
    data = await adapter.edit_webhook_message(
  File "/home/arc/club/pyhnix-beta/.venv/lib/python3.8/site-packages/discord/webhook/async_.py", line 221, in request
    raise HTTPException(response, data)
discord.errors.HTTPException: 401 Unauthorized (error code: 50027): Invalid Webhook Token

During handling of the above exception, another exception occurred:

Traceback (most recent call last):
  File "/home/arc/club/pyhnix-beta/.venv/lib/python3.8/site-packages/discord/ui/view.py", line 425, in _scheduled_task
    return await self.on_error(interaction, e, item)
  File "/home/arc/club/pyhnix-beta/ext/embed_builder.py", line 196, in on_error
    await interaction.followup.send(
  File "/home/arc/club/pyhnix-beta/.venv/lib/python3.8/site-packages/discord/webhook/async_.py", line 1726, in send
    data = await adapter.execute_webhook(
  File "/home/arc/club/pyhnix-beta/.venv/lib/python3.8/site-packages/discord/webhook/async_.py", line 221, in request
    raise HTTPException(response, data)
discord.errors.HTTPException: 401 Unauthorized (error code: 50027): Invalid Webhook Token
[2022-08-12 11:59:41 ()] | [40]: ext.embed_builder > an error occurred, 401 Unauthorized (error code: 50027): Invalid Webhook Token
[2022-08-12 11:59:41 ()] | [40]: asyncio > Task exception was never retrieved
future: <Task finished name='discord-ui-view-dispatch-77b9004f95e84616a154a2cb372a2321' coro=<View._scheduled_task() done, defined at /home/arc/club/pyhnix-beta/.venv/lib/python3.8/site-packages/discord/ui/view.py:414> exception=HTTPException('401 Unauthorized (error code: 50027): Invalid Webhook Token')>
Traceback (most recent call last):
  File "/home/arc/club/pyhnix-beta/.venv/lib/python3.8/site-packages/discord/ui/view.py", line 423, in _scheduled_task
    await item.callback(interaction)
  File "/home/arc/club/pyhnix-beta/ext/embed_builder.py", line 84, in _title
    await self.update(interaction)
  File "/home/arc/club/pyhnix-beta/ext/embed_builder.py", line 65, in update
    await interaction.followup.edit_message(
  File "/home/arc/club/pyhnix-beta/.venv/lib/python3.8/site-packages/discord/webhook/async_.py", line 1901, in edit_message
    data = await adapter.edit_webhook_message(
  File "/home/arc/club/pyhnix-beta/.venv/lib/python3.8/site-packages/discord/webhook/async_.py", line 221, in request
    raise HTTPException(response, data)
discord.errors.HTTPException: 401 Unauthorized (error code: 50027): Invalid Webhook Token

During handling of the above exception, another exception occurred:

Traceback (most recent call last):
  File "/home/arc/club/pyhnix-beta/.venv/lib/python3.8/site-packages/discord/ui/view.py", line 425, in _scheduled_task
    return await self.on_error(interaction, e, item)
  File "/home/arc/club/pyhnix-beta/ext/embed_builder.py", line 196, in on_error
    await interaction.followup.send(
  File "/home/arc/club/pyhnix-beta/.venv/lib/python3.8/site-packages/discord/webhook/async_.py", line 1726, in send
    data = await adapter.execute_webhook(
  File "/home/arc/club/pyhnix-beta/.venv/lib/python3.8/site-packages/discord/webhook/async_.py", line 221, in request
    raise HTTPException(response, data)
discord.errors.HTTPException: 401 Unauthorized (error code: 50027): Invalid Webhook Token
[2022-08-12 12:00:40 ()] | [40]: ext.embed_builder > an error occurred, 401 Unauthorized (error code: 50027): Invalid Webhook Token
[2022-08-12 12:00:40 ()] | [40]: asyncio > Task exception was never retrieved
future: <Task finished name='discord-ui-view-dispatch-77b9004f95e84616a154a2cb372a2321' coro=<View._scheduled_task() done, defined at /home/arc/club/pyhnix-beta/.venv/lib/python3.8/site-packages/discord/ui/view.py:414> exception=HTTPException('401 Unauthorized (error code: 50027): Invalid Webhook Token')>
Traceback (most recent call last):
  File "/home/arc/club/pyhnix-beta/.venv/lib/python3.8/site-packages/discord/ui/view.py", line 423, in _scheduled_task
    await item.callback(interaction)
  File "/home/arc/club/pyhnix-beta/ext/embed_builder.py", line 84, in _title
    await self.update(interaction)
  File "/home/arc/club/pyhnix-beta/ext/embed_builder.py", line 65, in update
    await interaction.followup.edit_message(
  File "/home/arc/club/pyhnix-beta/.venv/lib/python3.8/site-packages/discord/webhook/async_.py", line 1901, in edit_message
    data = await adapter.edit_webhook_message(
  File "/home/arc/club/pyhnix-beta/.venv/lib/python3.8/site-packages/discord/webhook/async_.py", line 221, in request
    raise HTTPException(response, data)
discord.errors.HTTPException: 401 Unauthorized (error code: 50027): Invalid Webhook Token

During handling of the above exception, another exception occurred:

Traceback (most recent call last):
  File "/home/arc/club/pyhnix-beta/.venv/lib/python3.8/site-packages/discord/ui/view.py", line 425, in _scheduled_task
    return await self.on_error(interaction, e, item)
  File "/home/arc/club/pyhnix-beta/ext/embed_builder.py", line 196, in on_error
    await interaction.followup.send(
  File "/home/arc/club/pyhnix-beta/.venv/lib/python3.8/site-packages/discord/webhook/async_.py", line 1726, in send
    data = await adapter.execute_webhook(
  File "/home/arc/club/pyhnix-beta/.venv/lib/python3.8/site-packages/discord/webhook/async_.py", line 221, in request
    raise HTTPException(response, data)
discord.errors.HTTPException: 401 Unauthorized (error code: 50027): Invalid Webhook Token
